<?xml version="1.0" ?>
<robot name="ustbot" xmlns:xacro="http://www.ros.org/wiki/xacro">

<xacro:include filename="$(find ustbot_description)/urdf/materials.xacro" />
<xacro:include filename="$(find ustbot_description)/urdf/ustbot.gazebo.xacro" />

  <link  name="base_footprint"/>
  <joint name="base_joint" type="fixed">
    <parent 
      link="base_footprint"/>
    <child 
      link="base_link"/>
    <origin 
      xyz="0.0 0.0 0.010" 
      rpy="0 0 0"/>
  </joint>

<link name="base_link">
  <inertial>
    <origin xyz="-5.181182074625435e-16 0.0 0.155331106352338" rpy="0 0 0"/>
    <mass value="54.59936129727744"/>
    <inertia ixx="3.18013" iyy="4.05832" izz="6.857677" ixy="-2.7e-05" iyz="-0.0" ixz="-0.0"/>
  </inertial>
  <visual>
    <origin xyz="0 0 0" rpy="0 0 0"/>
    <geometry>
      <mesh filename="package://ustbot_description/meshes/base_link.STL" scale="0.001 0.001 0.001"/>
    </geometry>
    
  </visual>
  <collision>
    <origin xyz="0 0 0" rpy="0 0 0"/>
    <geometry>
      <mesh filename="package://ustbot_description/meshes/base_link.STL" scale="0.001 0.001 0.001"/>
    </geometry>
  </collision>
</link>

<link name="wheel_right">
  <inertial>
    <origin xyz="1.215274427416404e-17 0.0 1.3877787807814457e-17" rpy="0 0 0"/>
    <mass value="1.3919984714020586"/>
    <inertia ixx="0.002937" iyy="0.004737" izz="0.002937" ixy="0.0" iyz="0.0" ixz="-0.0"/>
  </inertial>
  <visual>
    <origin xyz="-0.0 0.225 -0.0825" rpy="0 0 0"/>
    <geometry>
      <mesh filename="package://ustbot_description/meshes/wheel_right.STL" scale="0.001 0.001 0.001"/>
    </geometry>
    
  </visual>
  <collision>
    <origin xyz="-0.0 0.225 -0.0825" rpy="0 0 0"/>
    <geometry>
      <mesh filename="package://ustbot_description/meshes/wheel_right.STL" scale="0.001 0.001 0.001"/>
    </geometry>
  </collision>
</link>

<link name="wheel_left">
  <inertial>
    <origin xyz="1.215274427416404e-17 0.0 1.3877787807814457e-17" rpy="0 0 0"/>
    <mass value="1.3919984714020586"/>
    <inertia ixx="0.002937" iyy="0.004737" izz="0.002937" ixy="-0.0" iyz="0.0" ixz="-0.0"/>
  </inertial>
  <visual>
    <origin xyz="-0.0 -0.225 -0.0825" rpy="0 0 0"/>
    <geometry>
      <mesh filename="package://ustbot_description/meshes/wheel_left.STL" scale="0.001 0.001 0.001"/>
    </geometry>
    
  </visual>
  <collision>
    <origin xyz="-0.0 -0.225 -0.0825" rpy="0 0 0"/>
    <geometry>
      <mesh filename="package://ustbot_description/meshes/wheel_left.STL" scale="0.001 0.001 0.001"/>
    </geometry>
  </collision>
</link>

<link name="ultrasonic_front_right">
  <inertial>
    <origin xyz="0.0025000000000000577 -1.3013724642352287e-07 0.0" rpy="0 0 0"/>
    <mass value="0.04471200116533985"/>
    <inertia ixx="1e-05" iyy="2e-06" izz="8e-06" ixy="0.0" iyz="-0.0" ixz="-0.0"/>
  </inertial>
  <visual>
    <origin xyz="-0.44501 0.172077 -0.1955" rpy="0 0 0"/>
    <geometry>
      <mesh filename="package://ustbot_description/meshes/ultrasonic_front_right.STL" scale="0.001 0.001 0.001"/>
    </geometry>
    
  </visual>
  <collision>
    <origin xyz="-0.44501 0.172077 -0.1955" rpy="0 0 0"/>
    <geometry>
      <mesh filename="package://ustbot_description/meshes/ultrasonic_front_right.STL" scale="0.001 0.001 0.001"/>
    </geometry>
  </collision>
</link>

<link name="ultrasonic_front_left">
  <inertial>
    <origin xyz="0.0025000000000000577 1.3013724642352287e-07 0.0" rpy="0 0 0"/>
    <mass value="0.04471200116533985"/>
    <inertia ixx="1e-05" iyy="2e-06" izz="8e-06" ixy="-0.0" iyz="0.0" ixz="-0.0"/>
  </inertial>
  <visual>
    <origin xyz="-0.44501 -0.172077 -0.1955" rpy="0 0 0"/>
    <geometry>
      <mesh filename="package://ustbot_description/meshes/ultrasonic_front_left.STL" scale="0.001 0.001 0.001"/>
    </geometry>
    
  </visual>
  <collision>
    <origin xyz="-0.44501 -0.172077 -0.1955" rpy="0 0 0"/>
    <geometry>
      <mesh filename="package://ustbot_description/meshes/ultrasonic_front_left.STL" scale="0.001 0.001 0.001"/>
    </geometry>
  </collision>
</link>

<link name="ultrasonic_left_left">
  <inertial>
    <origin xyz="-1.88564546477199e-07 0.0025000000000000577 0.0" rpy="0 0 0"/>
    <mass value="0.04471200116533985"/>
    <inertia ixx="2e-06" iyy="1e-05" izz="8e-06" ixy="0.0" iyz="-0.0" ixz="0.0"/>
  </inertial>
  <visual>
    <origin xyz="-0.313812 -0.30001 -0.1955" rpy="0 0 0"/>
    <geometry>
      <mesh filename="package://ustbot_description/meshes/ultrasonic_left_left.STL" scale="0.001 0.001 0.001"/>
    </geometry>
    
  </visual>
  <collision>
    <origin xyz="-0.313812 -0.30001 -0.1955" rpy="0 0 0"/>
    <geometry>
      <mesh filename="package://ustbot_description/meshes/ultrasonic_left_left.STL" scale="0.001 0.001 0.001"/>
    </geometry>
  </collision>
</link>

<link name="ultrasonic_left_right">
  <inertial>
    <origin xyz="1.88564546477199e-07 0.0025000000000000577 0.0" rpy="0 0 0"/>
    <mass value="0.04471200116533985"/>
    <inertia ixx="2e-06" iyy="1e-05" izz="8e-06" ixy="-0.0" iyz="-0.0" ixz="-0.0"/>
  </inertial>
  <visual>
    <origin xyz="0.313812 -0.30001 -0.1955" rpy="0 0 0"/>
    <geometry>
      <mesh filename="package://ustbot_description/meshes/ultrasonic_left_right.STL" scale="0.001 0.001 0.001"/>
    </geometry>
    
  </visual>
  <collision>
    <origin xyz="0.313812 -0.30001 -0.1955" rpy="0 0 0"/>
    <geometry>
      <mesh filename="package://ustbot_description/meshes/ultrasonic_left_right.STL" scale="0.001 0.001 0.001"/>
    </geometry>
  </collision>
</link>

<link name="ultrasonic_back_left">
  <inertial>
    <origin xyz="-0.0025000000000000577 1.3013724642352287e-07 0.0" rpy="0 0 0"/>
    <mass value="0.044712001165339924"/>
    <inertia ixx="1e-05" iyy="2e-06" izz="8e-06" ixy="0.0" iyz="0.0" ixz="0.0"/>
  </inertial>
  <visual>
    <origin xyz="0.44501 -0.172077 -0.1955" rpy="0 0 0"/>
    <geometry>
      <mesh filename="package://ustbot_description/meshes/ultrasonic_back_left.STL" scale="0.001 0.001 0.001"/>
    </geometry>
    
  </visual>
  <collision>
    <origin xyz="0.44501 -0.172077 -0.1955" rpy="0 0 0"/>
    <geometry>
      <mesh filename="package://ustbot_description/meshes/ultrasonic_back_left.STL" scale="0.001 0.001 0.001"/>
    </geometry>
  </collision>
</link>

<link name="ultrasonic_back_right">
  <inertial>
    <origin xyz="-0.0025000000000000577 -1.3013724642352287e-07 0.0" rpy="0 0 0"/>
    <mass value="0.044712001165339924"/>
    <inertia ixx="1e-05" iyy="2e-06" izz="8e-06" ixy="-0.0" iyz="-0.0" ixz="0.0"/>
  </inertial>
  <visual>
    <origin xyz="0.44501 0.172077 -0.1955" rpy="0 0 0"/>
    <geometry>
      <mesh filename="package://ustbot_description/meshes/ultrasonic_back_right.STL" scale="0.001 0.001 0.001"/>
    </geometry>
    
  </visual>
  <collision>
    <origin xyz="0.44501 0.172077 -0.1955" rpy="0 0 0"/>
    <geometry>
      <mesh filename="package://ustbot_description/meshes/ultrasonic_back_right.STL" scale="0.001 0.001 0.001"/>
    </geometry>
  </collision>
</link>

<link name="ultrasonic_right_left">
  <inertial>
    <origin xyz="1.88564546477199e-07 -0.0025000000000000577 0.0" rpy="0 0 0"/>
    <mass value="0.04471200116533992"/>
    <inertia ixx="2e-06" iyy="1e-05" izz="8e-06" ixy="-0.0" iyz="0.0" ixz="0.0"/>
  </inertial>
  <visual>
    <origin xyz="0.313812 0.30001 -0.1955" rpy="0 0 0"/>
    <geometry>
      <mesh filename="package://ustbot_description/meshes/ultrasonic_right_left.STL" scale="0.001 0.001 0.001"/>
    </geometry>
    
  </visual>
  <collision>
    <origin xyz="0.313812 0.30001 -0.1955" rpy="0 0 0"/>
    <geometry>
      <mesh filename="package://ustbot_description/meshes/ultrasonic_right_left.STL" scale="0.001 0.001 0.001"/>
    </geometry>
  </collision>
</link>

<link name="ultrasonic_right_right">
  <inertial>
    <origin xyz="-1.8856454653271015e-07 -0.0025000000000000577 0.0" rpy="0 0 0"/>
    <mass value="0.04471200116533992"/>
    <inertia ixx="2e-06" iyy="1e-05" izz="8e-06" ixy="0.0" iyz="0.0" ixz="-0.0"/>
  </inertial>
  <visual>
    <origin xyz="-0.313812 0.30001 -0.1955" rpy="0 0 0"/>
    <geometry>
      <mesh filename="package://ustbot_description/meshes/ultrasonic_right_right.STL" scale="0.001 0.001 0.001"/>
    </geometry>
    
  </visual>
  <collision>
    <origin xyz="-0.313812 0.30001 -0.1955" rpy="0 0 0"/>
    <geometry>
      <mesh filename="package://ustbot_description/meshes/ultrasonic_right_right.STL" scale="0.001 0.001 0.001"/>
    </geometry>
  </collision>
</link>

<link name="lidar_front">
  <inertial>
    <origin xyz="-5.551115123125783e-17 5.551115123125783e-17 0.017500000000000016" rpy="0 0 0"/>
    <mass value="0.1356625159140251"/>
    <inertia ixx="5.8e-05" iyy="5.8e-05" izz="8.8e-05" ixy="0.0" iyz="0.0" ixz="0.0"/>
  </inertial>
  <visual>
    <origin xyz="-0.386 -0.241 -0.25751" rpy="0 0 0"/>
    <geometry>
      <mesh filename="package://ustbot_description/meshes/lidar_front.STL" scale="0.001 0.001 0.001"/>
    </geometry>
    
  </visual>
  <collision>
    <origin xyz="-0.386 -0.241 -0.25751" rpy="0 0 0"/>
    <geometry>
      <mesh filename="package://ustbot_description/meshes/lidar_front.STL" scale="0.001 0.001 0.001"/>
    </geometry>
  </collision>
</link>

<link name="lidar_back">
  <inertial>
    <origin xyz="0.0 0.0 0.01749999999999996" rpy="0 0 0"/>
    <mass value="0.1356625159140251"/>
    <inertia ixx="5.8e-05" iyy="5.8e-05" izz="8.8e-05" ixy="0.0" iyz="0.0" ixz="-0.0"/>
  </inertial>
  <visual>
    <origin xyz="0.386 0.241 -0.25751" rpy="0 0 0"/>
    <geometry>
      <mesh filename="package://ustbot_description/meshes/lidar_back.STL" scale="0.001 0.001 0.001"/>
    </geometry>
    
  </visual>
  <collision>
    <origin xyz="0.386 0.241 -0.25751" rpy="0 0 0"/>
    <geometry>
      <mesh filename="package://ustbot_description/meshes/lidar_back.STL" scale="0.001 0.001 0.001"/>
    </geometry>
  </collision>
</link>

<joint name="wheel_right_joint" type="continuous">
  <origin xyz="0.0 -0.225 0.0825" rpy="0 0 0"/>
  <parent link="base_link"/>
  <child link="wheel_right"/>
  <axis xyz="0.0 1.0 0.0"/>
</joint>

<joint name="wheel_left_joint" type="continuous">
  <origin xyz="0.0 0.225 0.0825" rpy="0 0 0"/>
  <parent link="base_link"/>
  <child link="wheel_left"/>
  <axis xyz="0.0 1.0 0.0"/>
</joint>

<joint name="ultrasonic_front_right" type="fixed">
  <origin xyz="0.44501 -0.172077 0.1955" rpy="0 0 0"/>
  <parent link="base_link"/>
  <child link="ultrasonic_front_right"/>
</joint>

<joint name="ultrasonic_front_left" type="fixed">
  <origin xyz="0.44501 0.172077 0.1955" rpy="0 0 0"/>
  <parent link="base_link"/>
  <child link="ultrasonic_front_left"/>
</joint>

<joint name="ultrasonic_left_front" type="fixed">
  <origin xyz="0.313812 0.30001 0.1955" rpy="0 0 0"/>
  <parent link="base_link"/>
  <child link="ultrasonic_left_left"/>
</joint>

<joint name="ultrasonic_left_back" type="fixed">
  <origin xyz="-0.313812 0.30001 0.1955" rpy="0 0 0"/>
  <parent link="base_link"/>
  <child link="ultrasonic_left_right"/>
</joint>

<joint name="ultrasonic_back_left" type="fixed">
  <origin xyz="-0.44501 0.172077 0.1955" rpy="0 0 0"/>
  <parent link="base_link"/>
  <child link="ultrasonic_back_left"/>
</joint>

<joint name="ultrasonic_back_right" type="fixed">
  <origin xyz="-0.44501 -0.172077 0.1955" rpy="0 0 0"/>
  <parent link="base_link"/>
  <child link="ultrasonic_back_right"/>
</joint>

<joint name="ultrasonic_right_back" type="fixed">
  <origin xyz="-0.313812 -0.30001 0.1955" rpy="0 0 0"/>
  <parent link="base_link"/>
  <child link="ultrasonic_right_left"/>
</joint>

<joint name="ultrasonic_right_front" type="fixed">
  <origin xyz="0.313812 -0.30001 0.1955" rpy="0 0 0"/>
  <parent link="base_link"/>
  <child link="ultrasonic_right_right"/>
</joint>

<joint name="lidar_front_joint" type="fixed">
  <origin xyz="0.386 0.241 0.25751" rpy="0 0 0"/>
  <parent link="base_link"/>
  <child link="lidar_front"/>
  <axis xyz="0.0 0.0 1.0"/>
</joint>

<joint name="lidar_back_joint" type="fixed">
  <origin xyz="-0.386 -0.241 0.25751" rpy="0 0 0"/>
  <parent link="base_link"/>
  <child link="lidar_back"/>
  <axis xyz="0.0 0.0 1.0"/>
</joint>


<transmission name="wheel_right_joint_tran">
  <type>transmission_interface/SimpleTransmission</type>
  <joint name="wheel_right_joint">
    <hardwareInterface>hardware_interface/VelocityJointInterface</hardwareInterface>
  </joint>
  <actuator name="wheel_right_joint_actuator">
    <hardwareInterface>hardware_interface/VelocityJointInterface</hardwareInterface>
    <mechanicalReduction>1</mechanicalReduction>
  </actuator>
</transmission>

<transmission name="wheel_left_joint_tran">
  <type>transmission_interface/SimpleTransmission</type>
  <joint name="wheel_left_joint">
    <hardwareInterface>hardware_interface/VelocityJointInterface</hardwareInterface>
  </joint>
  <actuator name="wheel_left_joint_actuator">
    <hardwareInterface>hardware_interface/VelocityJointInterface</hardwareInterface>
    <mechanicalReduction>1</mechanicalReduction>
  </actuator>
</transmission>

</robot>
